#Expyriment 0.11.dev5 (Python 3.12.0), .xpe-file, coding: UTF-8
#date: Wed Oct 16 2024 14:39:19
#sha1: 201787
#modules: 
#display: size=(800, 600), window_mode=True, opengl=2
#os: uname_result(system='Linux', node='is154920', release='6.8.0-45-lowlatency', version='#45.1~22.04.1-Ubuntu SMP PREEMPT_DYNAMIC Fri Sep  6 15:26:10 UTC', machine='x86_64')
Time,Type,Event,Value,Detail,Detail2
403,stderr,received,'Traceback (most recent call last):'
403,stderr,received,'  File "/home/cp983411/00_git/ppe/experiments/kinematogram/random_walk1.py", line 20, in <module>'
404,stderr,received,'    dots = [stimuli.Circle(RADIUS,'
404,stderr,received,'            ^^^^^^^^^^^^^^^^^^^^^^'
404,stderr,received,'  File "/home/cp983411/.pyenv/versions/expyriment-py3.12-0.11.0.dev3/lib/python3.12/site-packages/expyriment/stimuli/_circle.py", line 49, in __init__'
404,stderr,received,'    elif line_width < 0 or line_width >= self._radius:'
404,stderr,received,'         ^^^^^^^^^^^^^^'
404,stderr,received,"TypeError: '<' not supported between instances of 'tuple' and 'int'"
